Internal Server Error: /api/personalize/itineraries/create/
Traceback (most recent call last):
  File "C:\Users\shahoraiar\Desktop\Travel-Assistant\venv\Lib\site-packages\asgiref\sync.py", line 489, in thread_handler
    raise exc_info[1]
  File "C:\Users\shahoraiar\Desktop\Travel-Assistant\venv\Lib\site-packages\django\core\handlers\exception.py", line 42, in inner
    response = await get_response(request)
               ^^^^^^^^^^^^^^^^^^^^^^^^^^^
  File "C:\Users\shahoraiar\Desktop\Travel-Assistant\venv\Lib\site-packages\asgiref\sync.py", line 489, in thread_handler
    raise exc_info[1]
  File "C:\Users\shahoraiar\Desktop\Travel-Assistant\venv\Lib\site-packages\django\core\handlers\base.py", line 253, in _get_response_async
    response = await wrapped_callback(
               ^^^^^^^^^^^^^^^^^^^^^^^
        request, *callback_args, **callback_kwargs
        ^^^^^^^^^^^^^^^^^^^^^^^^^^^^^^^^^^^^^^^^^^
    )
    ^
  File "C:\Users\shahoraiar\Desktop\Travel-Assistant\venv\Lib\site-packages\asgiref\sync.py", line 439, in __call__
    ret = await asyncio.shield(exec_coro)
          ^^^^^^^^^^^^^^^^^^^^^^^^^^^^^^^
  File "C:\Program Files\Python313\Lib\concurrent\futures\thread.py", line 59, in run
    result = self.fn(*self.args, **self.kwargs)
  File "C:\Users\shahoraiar\Desktop\Travel-Assistant\venv\Lib\site-packages\asgiref\sync.py", line 493, in thread_handler
    return func(*args, **kwargs)
  File "C:\Users\shahoraiar\Desktop\Travel-Assistant\venv\Lib\site-packages\django\views\decorators\csrf.py", line 65, in _view_wrapper
    return view_func(request, *args, **kwargs)
  File "C:\Users\shahoraiar\Desktop\Travel-Assistant\venv\Lib\site-packages\django\views\generic\base.py", line 105, in view
    return self.dispatch(request, *args, **kwargs)
           ~~~~~~~~~~~~~^^^^^^^^^^^^^^^^^^^^^^^^^^
  File "C:\Users\shahoraiar\Desktop\Travel-Assistant\venv\Lib\site-packages\rest_framework\views.py", line 515, in dispatch
    response = self.handle_exception(exc)
  File "C:\Users\shahoraiar\Desktop\Travel-Assistant\venv\Lib\site-packages\rest_framework\views.py", line 475, in handle_exception
    self.raise_uncaught_exception(exc)
    ~~~~~~~~~~~~~~~~~~~~~~~~~~~~~^^^^^
  File "C:\Users\shahoraiar\Desktop\Travel-Assistant\venv\Lib\site-packages\rest_framework\views.py", line 486, in raise_uncaught_exception
    raise exc
  File "C:\Users\shahoraiar\Desktop\Travel-Assistant\venv\Lib\site-packages\rest_framework\views.py", line 512, in dispatch
    response = handler(request, *args, **kwargs)
  File "C:\Users\shahoraiar\Desktop\Travel-Assistant\venv\Lib\site-packages\rest_framework\decorators.py", line 50, in handler
    return func(*args, **kwargs)
  File "C:\Users\shahoraiar\Desktop\Travel-Assistant\personalize\views.py", line 138, in create_itinerary
    print('user preferences: ', user_preferences)
    ~~~~~^^^^^^^^^^^^^^^^^^^^^^^^^^^^^^^^^^^^^^^^
  File "C:\Users\shahoraiar\Desktop\Travel-Assistant\venv\Lib\site-packages\django\db\models\query.py", line 363, in __repr__
    return "<%s %r>" % (self.__class__.__name__, data)
                                                 ^^^^
  File "C:\Users\shahoraiar\Desktop\Travel-Assistant\venv\Lib\site-packages\django\db\models\base.py", line 590, in __repr__
    return "<%s: %s>" % (self.__class__.__name__, self)
                                                  ^^^^
  File "C:\Users\shahoraiar\Desktop\Travel-Assistant\personalize\models.py", line 31, in __str__
    prefs = ", ".join([p.name for p in self.preferences.all()])
                                       ^^^^^^^^^^^^^^^^^^^^
AttributeError: 'Interest' object has no attribute 'all'
[35;1mHTTP POST /api/personalize/itineraries/create/ 500 [0.48, 172.28.176.1:53326][0m
Internal Server Error: /api/personalize/itineraries/create/
Traceback (most recent call last):
  File "C:\Users\shahoraiar\Desktop\Travel-Assistant\venv\Lib\site-packages\asgiref\sync.py", line 489, in thread_handler
    raise exc_info[1]
  File "C:\Users\shahoraiar\Desktop\Travel-Assistant\venv\Lib\site-packages\django\core\handlers\exception.py", line 42, in inner
    response = await get_response(request)
               ^^^^^^^^^^^^^^^^^^^^^^^^^^^
  File "C:\Users\shahoraiar\Desktop\Travel-Assistant\venv\Lib\site-packages\asgiref\sync.py", line 489, in thread_handler
    raise exc_info[1]
  File "C:\Users\shahoraiar\Desktop\Travel-Assistant\venv\Lib\site-packages\django\core\handlers\base.py", line 253, in _get_response_async
    response = await wrapped_callback(
               ^^^^^^^^^^^^^^^^^^^^^^^
        request, *callback_args, **callback_kwargs
        ^^^^^^^^^^^^^^^^^^^^^^^^^^^^^^^^^^^^^^^^^^
    )
    ^
  File "C:\Users\shahoraiar\Desktop\Travel-Assistant\venv\Lib\site-packages\asgiref\sync.py", line 439, in __call__
    ret = await asyncio.shield(exec_coro)
          ^^^^^^^^^^^^^^^^^^^^^^^^^^^^^^^
  File "C:\Program Files\Python313\Lib\concurrent\futures\thread.py", line 59, in run
    result = self.fn(*self.args, **self.kwargs)
  File "C:\Users\shahoraiar\Desktop\Travel-Assistant\venv\Lib\site-packages\asgiref\sync.py", line 493, in thread_handler
    return func(*args, **kwargs)
  File "C:\Users\shahoraiar\Desktop\Travel-Assistant\venv\Lib\site-packages\django\views\decorators\csrf.py", line 65, in _view_wrapper
    return view_func(request, *args, **kwargs)
  File "C:\Users\shahoraiar\Desktop\Travel-Assistant\venv\Lib\site-packages\django\views\generic\base.py", line 105, in view
    return self.dispatch(request, *args, **kwargs)
           ~~~~~~~~~~~~~^^^^^^^^^^^^^^^^^^^^^^^^^^
  File "C:\Users\shahoraiar\Desktop\Travel-Assistant\venv\Lib\site-packages\rest_framework\views.py", line 515, in dispatch
    response = self.handle_exception(exc)
  File "C:\Users\shahoraiar\Desktop\Travel-Assistant\venv\Lib\site-packages\rest_framework\views.py", line 475, in handle_exception
    self.raise_uncaught_exception(exc)
    ~~~~~~~~~~~~~~~~~~~~~~~~~~~~~^^^^^
  File "C:\Users\shahoraiar\Desktop\Travel-Assistant\venv\Lib\site-packages\rest_framework\views.py", line 486, in raise_uncaught_exception
    raise exc
  File "C:\Users\shahoraiar\Desktop\Travel-Assistant\venv\Lib\site-packages\rest_framework\views.py", line 512, in dispatch
    response = handler(request, *args, **kwargs)
  File "C:\Users\shahoraiar\Desktop\Travel-Assistant\venv\Lib\site-packages\rest_framework\decorators.py", line 50, in handler
    return func(*args, **kwargs)
  File "C:\Users\shahoraiar\Desktop\Travel-Assistant\personalize\views.py", line 138, in create_itinerary
    print('user preferences: ', user_preferences)
    ~~~~~^^^^^^^^^^^^^^^^^^^^^^^^^^^^^^^^^^^^^^^^
  File "C:\Users\shahoraiar\Desktop\Travel-Assistant\venv\Lib\site-packages\django\db\models\query.py", line 363, in __repr__
    return "<%s %r>" % (self.__class__.__name__, data)
                                                 ^^^^
  File "C:\Users\shahoraiar\Desktop\Travel-Assistant\venv\Lib\site-packages\django\db\models\base.py", line 590, in __repr__
    return "<%s: %s>" % (self.__class__.__name__, self)
                                                  ^^^^
  File "C:\Users\shahoraiar\Desktop\Travel-Assistant\personalize\models.py", line 31, in __str__
    prefs = ", ".join([p.name for p in self.preferences.all()])
                                       ^^^^^^^^^^^^^^^^^^^^
AttributeError: 'Interest' object has no attribute 'all'
[35;1mHTTP POST /api/personalize/itineraries/create/ 500 [0.05, 172.28.176.1:58714][0m
Internal Server Error: /api/personalize/itineraries/create/
Traceback (most recent call last):
  File "C:\Users\shahoraiar\Desktop\Travel-Assistant\venv\Lib\site-packages\asgiref\sync.py", line 489, in thread_handler
    raise exc_info[1]
  File "C:\Users\shahoraiar\Desktop\Travel-Assistant\venv\Lib\site-packages\django\core\handlers\exception.py", line 42, in inner
    response = await get_response(request)
               ^^^^^^^^^^^^^^^^^^^^^^^^^^^
  File "C:\Users\shahoraiar\Desktop\Travel-Assistant\venv\Lib\site-packages\asgiref\sync.py", line 489, in thread_handler
    raise exc_info[1]
  File "C:\Users\shahoraiar\Desktop\Travel-Assistant\venv\Lib\site-packages\django\core\handlers\base.py", line 253, in _get_response_async
    response = await wrapped_callback(
               ^^^^^^^^^^^^^^^^^^^^^^^
        request, *callback_args, **callback_kwargs
        ^^^^^^^^^^^^^^^^^^^^^^^^^^^^^^^^^^^^^^^^^^
    )
    ^
  File "C:\Users\shahoraiar\Desktop\Travel-Assistant\venv\Lib\site-packages\asgiref\sync.py", line 439, in __call__
    ret = await asyncio.shield(exec_coro)
          ^^^^^^^^^^^^^^^^^^^^^^^^^^^^^^^
  File "C:\Program Files\Python313\Lib\concurrent\futures\thread.py", line 59, in run
    result = self.fn(*self.args, **self.kwargs)
  File "C:\Users\shahoraiar\Desktop\Travel-Assistant\venv\Lib\site-packages\asgiref\sync.py", line 493, in thread_handler
    return func(*args, **kwargs)
  File "C:\Users\shahoraiar\Desktop\Travel-Assistant\venv\Lib\site-packages\django\views\decorators\csrf.py", line 65, in _view_wrapper
    return view_func(request, *args, **kwargs)
  File "C:\Users\shahoraiar\Desktop\Travel-Assistant\venv\Lib\site-packages\django\views\generic\base.py", line 105, in view
    return self.dispatch(request, *args, **kwargs)
           ~~~~~~~~~~~~~^^^^^^^^^^^^^^^^^^^^^^^^^^
  File "C:\Users\shahoraiar\Desktop\Travel-Assistant\venv\Lib\site-packages\rest_framework\views.py", line 515, in dispatch
    response = self.handle_exception(exc)
  File "C:\Users\shahoraiar\Desktop\Travel-Assistant\venv\Lib\site-packages\rest_framework\views.py", line 475, in handle_exception
    self.raise_uncaught_exception(exc)
    ~~~~~~~~~~~~~~~~~~~~~~~~~~~~~^^^^^
  File "C:\Users\shahoraiar\Desktop\Travel-Assistant\venv\Lib\site-packages\rest_framework\views.py", line 486, in raise_uncaught_exception
    raise exc
  File "C:\Users\shahoraiar\Desktop\Travel-Assistant\venv\Lib\site-packages\rest_framework\views.py", line 512, in dispatch
    response = handler(request, *args, **kwargs)
  File "C:\Users\shahoraiar\Desktop\Travel-Assistant\venv\Lib\site-packages\rest_framework\decorators.py", line 50, in handler
    return func(*args, **kwargs)
  File "C:\Users\shahoraiar\Desktop\Travel-Assistant\personalize\views.py", line 138, in create_itinerary
    print('user preferences: ', user_preferences)
    ~~~~~^^^^^^^^^^^^^^^^^^^^^^^^^^^^^^^^^^^^^^^^
  File "C:\Users\shahoraiar\Desktop\Travel-Assistant\venv\Lib\site-packages\django\db\models\query.py", line 363, in __repr__
    return "<%s %r>" % (self.__class__.__name__, data)
                                                 ^^^^
  File "C:\Users\shahoraiar\Desktop\Travel-Assistant\venv\Lib\site-packages\django\db\models\base.py", line 590, in __repr__
    return "<%s: %s>" % (self.__class__.__name__, self)
                                                  ^^^^
  File "C:\Users\shahoraiar\Desktop\Travel-Assistant\personalize\models.py", line 31, in __str__
    prefs = ", ".join([p.name for p in self.preferences.all()])
                                       ^^^^^^^^^^^^^^^^^^^^
AttributeError: 'Interest' object has no attribute 'all'
[35;1mHTTP POST /api/personalize/itineraries/create/ 500 [0.03, 172.28.176.1:58714][0m
Internal Server Error: /api/personalize/itineraries/create/
Traceback (most recent call last):
  File "C:\Users\shahoraiar\Desktop\Travel-Assistant\venv\Lib\site-packages\asgiref\sync.py", line 489, in thread_handler
    raise exc_info[1]
  File "C:\Users\shahoraiar\Desktop\Travel-Assistant\venv\Lib\site-packages\django\core\handlers\exception.py", line 42, in inner
    response = await get_response(request)
               ^^^^^^^^^^^^^^^^^^^^^^^^^^^
  File "C:\Users\shahoraiar\Desktop\Travel-Assistant\venv\Lib\site-packages\asgiref\sync.py", line 489, in thread_handler
    raise exc_info[1]
  File "C:\Users\shahoraiar\Desktop\Travel-Assistant\venv\Lib\site-packages\django\core\handlers\base.py", line 253, in _get_response_async
    response = await wrapped_callback(
               ^^^^^^^^^^^^^^^^^^^^^^^
        request, *callback_args, **callback_kwargs
        ^^^^^^^^^^^^^^^^^^^^^^^^^^^^^^^^^^^^^^^^^^
    )
    ^
  File "C:\Users\shahoraiar\Desktop\Travel-Assistant\venv\Lib\site-packages\asgiref\sync.py", line 439, in __call__
    ret = await asyncio.shield(exec_coro)
          ^^^^^^^^^^^^^^^^^^^^^^^^^^^^^^^
  File "C:\Program Files\Python313\Lib\concurrent\futures\thread.py", line 59, in run
    result = self.fn(*self.args, **self.kwargs)
  File "C:\Users\shahoraiar\Desktop\Travel-Assistant\venv\Lib\site-packages\asgiref\sync.py", line 493, in thread_handler
    return func(*args, **kwargs)
  File "C:\Users\shahoraiar\Desktop\Travel-Assistant\venv\Lib\site-packages\django\views\decorators\csrf.py", line 65, in _view_wrapper
    return view_func(request, *args, **kwargs)
  File "C:\Users\shahoraiar\Desktop\Travel-Assistant\venv\Lib\site-packages\django\views\generic\base.py", line 105, in view
    return self.dispatch(request, *args, **kwargs)
           ~~~~~~~~~~~~~^^^^^^^^^^^^^^^^^^^^^^^^^^
  File "C:\Users\shahoraiar\Desktop\Travel-Assistant\venv\Lib\site-packages\rest_framework\views.py", line 515, in dispatch
    response = self.handle_exception(exc)
  File "C:\Users\shahoraiar\Desktop\Travel-Assistant\venv\Lib\site-packages\rest_framework\views.py", line 475, in handle_exception
    self.raise_uncaught_exception(exc)
    ~~~~~~~~~~~~~~~~~~~~~~~~~~~~~^^^^^
  File "C:\Users\shahoraiar\Desktop\Travel-Assistant\venv\Lib\site-packages\rest_framework\views.py", line 486, in raise_uncaught_exception
    raise exc
  File "C:\Users\shahoraiar\Desktop\Travel-Assistant\venv\Lib\site-packages\rest_framework\views.py", line 512, in dispatch
    response = handler(request, *args, **kwargs)
  File "C:\Users\shahoraiar\Desktop\Travel-Assistant\venv\Lib\site-packages\rest_framework\decorators.py", line 50, in handler
    return func(*args, **kwargs)
  File "C:\Users\shahoraiar\Desktop\Travel-Assistant\personalize\views.py", line 138, in create_itinerary
    print('user preferences: ', user_preferences)
    ~~~~~^^^^^^^^^^^^^^^^^^^^^^^^^^^^^^^^^^^^^^^^
  File "C:\Users\shahoraiar\Desktop\Travel-Assistant\venv\Lib\site-packages\django\db\models\query.py", line 363, in __repr__
    return "<%s %r>" % (self.__class__.__name__, data)
                                                 ^^^^
  File "C:\Users\shahoraiar\Desktop\Travel-Assistant\venv\Lib\site-packages\django\db\models\base.py", line 590, in __repr__
    return "<%s: %s>" % (self.__class__.__name__, self)
                                                  ^^^^
  File "C:\Users\shahoraiar\Desktop\Travel-Assistant\personalize\models.py", line 31, in __str__
    prefs = ", ".join([p.name for p in self.preferences.all()])
                                       ^^^^^^^^^^^^^^^^^^^^
AttributeError: 'Interest' object has no attribute 'all'
[35;1mHTTP POST /api/personalize/itineraries/create/ 500 [0.04, 172.28.176.1:51148][0m
Internal Server Error: /api/personalize/itineraries/create/
Traceback (most recent call last):
  File "C:\Users\shahoraiar\Desktop\Travel-Assistant\venv\Lib\site-packages\asgiref\sync.py", line 489, in thread_handler
    raise exc_info[1]
  File "C:\Users\shahoraiar\Desktop\Travel-Assistant\venv\Lib\site-packages\django\core\handlers\exception.py", line 42, in inner
    response = await get_response(request)
               ^^^^^^^^^^^^^^^^^^^^^^^^^^^
  File "C:\Users\shahoraiar\Desktop\Travel-Assistant\venv\Lib\site-packages\asgiref\sync.py", line 489, in thread_handler
    raise exc_info[1]
  File "C:\Users\shahoraiar\Desktop\Travel-Assistant\venv\Lib\site-packages\django\core\handlers\base.py", line 253, in _get_response_async
    response = await wrapped_callback(
               ^^^^^^^^^^^^^^^^^^^^^^^
        request, *callback_args, **callback_kwargs
        ^^^^^^^^^^^^^^^^^^^^^^^^^^^^^^^^^^^^^^^^^^
    )
    ^
  File "C:\Users\shahoraiar\Desktop\Travel-Assistant\venv\Lib\site-packages\asgiref\sync.py", line 439, in __call__
    ret = await asyncio.shield(exec_coro)
          ^^^^^^^^^^^^^^^^^^^^^^^^^^^^^^^
  File "C:\Program Files\Python313\Lib\concurrent\futures\thread.py", line 59, in run
    result = self.fn(*self.args, **self.kwargs)
  File "C:\Users\shahoraiar\Desktop\Travel-Assistant\venv\Lib\site-packages\asgiref\sync.py", line 493, in thread_handler
    return func(*args, **kwargs)
  File "C:\Users\shahoraiar\Desktop\Travel-Assistant\venv\Lib\site-packages\django\views\decorators\csrf.py", line 65, in _view_wrapper
    return view_func(request, *args, **kwargs)
  File "C:\Users\shahoraiar\Desktop\Travel-Assistant\venv\Lib\site-packages\django\views\generic\base.py", line 105, in view
    return self.dispatch(request, *args, **kwargs)
           ~~~~~~~~~~~~~^^^^^^^^^^^^^^^^^^^^^^^^^^
  File "C:\Users\shahoraiar\Desktop\Travel-Assistant\venv\Lib\site-packages\rest_framework\views.py", line 515, in dispatch
    response = self.handle_exception(exc)
  File "C:\Users\shahoraiar\Desktop\Travel-Assistant\venv\Lib\site-packages\rest_framework\views.py", line 475, in handle_exception
    self.raise_uncaught_exception(exc)
    ~~~~~~~~~~~~~~~~~~~~~~~~~~~~~^^^^^
  File "C:\Users\shahoraiar\Desktop\Travel-Assistant\venv\Lib\site-packages\rest_framework\views.py", line 486, in raise_uncaught_exception
    raise exc
  File "C:\Users\shahoraiar\Desktop\Travel-Assistant\venv\Lib\site-packages\rest_framework\views.py", line 512, in dispatch
    response = handler(request, *args, **kwargs)
  File "C:\Users\shahoraiar\Desktop\Travel-Assistant\venv\Lib\site-packages\rest_framework\decorators.py", line 50, in handler
    return func(*args, **kwargs)
  File "C:\Users\shahoraiar\Desktop\Travel-Assistant\personalize\views.py", line 138, in create_itinerary
    print('user preferences: ', user_preferences)
    ~~~~~^^^^^^^^^^^^^^^^^^^^^^^^^^^^^^^^^^^^^^^^
  File "C:\Users\shahoraiar\Desktop\Travel-Assistant\venv\Lib\site-packages\django\db\models\query.py", line 363, in __repr__
    return "<%s %r>" % (self.__class__.__name__, data)
                                                 ^^^^
  File "C:\Users\shahoraiar\Desktop\Travel-Assistant\venv\Lib\site-packages\django\db\models\base.py", line 590, in __repr__
    return "<%s: %s>" % (self.__class__.__name__, self)
                                                  ^^^^
  File "C:\Users\shahoraiar\Desktop\Travel-Assistant\personalize\models.py", line 31, in __str__
    prefs = ", ".join([p.name for p in self.preferences.all()])
                                       ^^^^^^^^^^^^^^^^^^^^
AttributeError: 'Interest' object has no attribute 'all'
[35;1mHTTP POST /api/personalize/itineraries/create/ 500 [0.03, 172.28.176.1:51148][0m
Internal Server Error: /api/personalize/itineraries/create/
Traceback (most recent call last):
  File "C:\Users\shahoraiar\Desktop\Travel-Assistant\venv\Lib\site-packages\asgiref\sync.py", line 489, in thread_handler
    raise exc_info[1]
  File "C:\Users\shahoraiar\Desktop\Travel-Assistant\venv\Lib\site-packages\django\core\handlers\exception.py", line 42, in inner
    response = await get_response(request)
               ^^^^^^^^^^^^^^^^^^^^^^^^^^^
  File "C:\Users\shahoraiar\Desktop\Travel-Assistant\venv\Lib\site-packages\asgiref\sync.py", line 489, in thread_handler
    raise exc_info[1]
  File "C:\Users\shahoraiar\Desktop\Travel-Assistant\venv\Lib\site-packages\django\core\handlers\base.py", line 253, in _get_response_async
    response = await wrapped_callback(
               ^^^^^^^^^^^^^^^^^^^^^^^
        request, *callback_args, **callback_kwargs
        ^^^^^^^^^^^^^^^^^^^^^^^^^^^^^^^^^^^^^^^^^^
    )
    ^
  File "C:\Users\shahoraiar\Desktop\Travel-Assistant\venv\Lib\site-packages\asgiref\sync.py", line 439, in __call__
    ret = await asyncio.shield(exec_coro)
          ^^^^^^^^^^^^^^^^^^^^^^^^^^^^^^^
  File "C:\Program Files\Python313\Lib\concurrent\futures\thread.py", line 59, in run
    result = self.fn(*self.args, **self.kwargs)
  File "C:\Users\shahoraiar\Desktop\Travel-Assistant\venv\Lib\site-packages\asgiref\sync.py", line 493, in thread_handler
    return func(*args, **kwargs)
  File "C:\Users\shahoraiar\Desktop\Travel-Assistant\venv\Lib\site-packages\django\views\decorators\csrf.py", line 65, in _view_wrapper
    return view_func(request, *args, **kwargs)
  File "C:\Users\shahoraiar\Desktop\Travel-Assistant\venv\Lib\site-packages\django\views\generic\base.py", line 105, in view
    return self.dispatch(request, *args, **kwargs)
           ~~~~~~~~~~~~~^^^^^^^^^^^^^^^^^^^^^^^^^^
  File "C:\Users\shahoraiar\Desktop\Travel-Assistant\venv\Lib\site-packages\rest_framework\views.py", line 515, in dispatch
    response = self.handle_exception(exc)
  File "C:\Users\shahoraiar\Desktop\Travel-Assistant\venv\Lib\site-packages\rest_framework\views.py", line 475, in handle_exception
    self.raise_uncaught_exception(exc)
    ~~~~~~~~~~~~~~~~~~~~~~~~~~~~~^^^^^
  File "C:\Users\shahoraiar\Desktop\Travel-Assistant\venv\Lib\site-packages\rest_framework\views.py", line 486, in raise_uncaught_exception
    raise exc
  File "C:\Users\shahoraiar\Desktop\Travel-Assistant\venv\Lib\site-packages\rest_framework\views.py", line 512, in dispatch
    response = handler(request, *args, **kwargs)
  File "C:\Users\shahoraiar\Desktop\Travel-Assistant\venv\Lib\site-packages\rest_framework\decorators.py", line 50, in handler
    return func(*args, **kwargs)
  File "C:\Users\shahoraiar\Desktop\Travel-Assistant\personalize\views.py", line 138, in create_itinerary
    print('user preferences: ', user_preferences)
    ~~~~~^^^^^^^^^^^^^^^^^^^^^^^^^^^^^^^^^^^^^^^^
  File "C:\Users\shahoraiar\Desktop\Travel-Assistant\venv\Lib\site-packages\django\db\models\query.py", line 363, in __repr__
    return "<%s %r>" % (self.__class__.__name__, data)
                                                 ^^^^
  File "C:\Users\shahoraiar\Desktop\Travel-Assistant\venv\Lib\site-packages\django\db\models\base.py", line 590, in __repr__
    return "<%s: %s>" % (self.__class__.__name__, self)
                                                  ^^^^
  File "C:\Users\shahoraiar\Desktop\Travel-Assistant\personalize\models.py", line 31, in __str__
    prefs = ", ".join([p.name for p in self.preferences.all()])
                                       ^^^^^^^^^^^^^^^^^^^^
AttributeError: 'Interest' object has no attribute 'all'
[35;1mHTTP POST /api/personalize/itineraries/create/ 500 [0.02, 172.28.176.1:51148][0m
Internal Server Error: /api/personalize/itineraries/create/
Traceback (most recent call last):
  File "C:\Users\shahoraiar\Desktop\Travel-Assistant\venv\Lib\site-packages\asgiref\sync.py", line 489, in thread_handler
    raise exc_info[1]
  File "C:\Users\shahoraiar\Desktop\Travel-Assistant\venv\Lib\site-packages\django\core\handlers\exception.py", line 42, in inner
    response = await get_response(request)
               ^^^^^^^^^^^^^^^^^^^^^^^^^^^
  File "C:\Users\shahoraiar\Desktop\Travel-Assistant\venv\Lib\site-packages\asgiref\sync.py", line 489, in thread_handler
    raise exc_info[1]
  File "C:\Users\shahoraiar\Desktop\Travel-Assistant\venv\Lib\site-packages\django\core\handlers\base.py", line 253, in _get_response_async
    response = await wrapped_callback(
               ^^^^^^^^^^^^^^^^^^^^^^^
        request, *callback_args, **callback_kwargs
        ^^^^^^^^^^^^^^^^^^^^^^^^^^^^^^^^^^^^^^^^^^
    )
    ^
  File "C:\Users\shahoraiar\Desktop\Travel-Assistant\venv\Lib\site-packages\asgiref\sync.py", line 439, in __call__
    ret = await asyncio.shield(exec_coro)
          ^^^^^^^^^^^^^^^^^^^^^^^^^^^^^^^
  File "C:\Program Files\Python313\Lib\concurrent\futures\thread.py", line 59, in run
    result = self.fn(*self.args, **self.kwargs)
  File "C:\Users\shahoraiar\Desktop\Travel-Assistant\venv\Lib\site-packages\asgiref\sync.py", line 493, in thread_handler
    return func(*args, **kwargs)
  File "C:\Users\shahoraiar\Desktop\Travel-Assistant\venv\Lib\site-packages\django\views\decorators\csrf.py", line 65, in _view_wrapper
    return view_func(request, *args, **kwargs)
  File "C:\Users\shahoraiar\Desktop\Travel-Assistant\venv\Lib\site-packages\django\views\generic\base.py", line 105, in view
    return self.dispatch(request, *args, **kwargs)
           ~~~~~~~~~~~~~^^^^^^^^^^^^^^^^^^^^^^^^^^
  File "C:\Users\shahoraiar\Desktop\Travel-Assistant\venv\Lib\site-packages\rest_framework\views.py", line 515, in dispatch
    response = self.handle_exception(exc)
  File "C:\Users\shahoraiar\Desktop\Travel-Assistant\venv\Lib\site-packages\rest_framework\views.py", line 475, in handle_exception
    self.raise_uncaught_exception(exc)
    ~~~~~~~~~~~~~~~~~~~~~~~~~~~~~^^^^^
  File "C:\Users\shahoraiar\Desktop\Travel-Assistant\venv\Lib\site-packages\rest_framework\views.py", line 486, in raise_uncaught_exception
    raise exc
  File "C:\Users\shahoraiar\Desktop\Travel-Assistant\venv\Lib\site-packages\rest_framework\views.py", line 512, in dispatch
    response = handler(request, *args, **kwargs)
  File "C:\Users\shahoraiar\Desktop\Travel-Assistant\venv\Lib\site-packages\rest_framework\decorators.py", line 50, in handler
    return func(*args, **kwargs)
  File "C:\Users\shahoraiar\Desktop\Travel-Assistant\personalize\views.py", line 138, in create_itinerary
    print('user preferences: ', user_preferences)
    ~~~~~^^^^^^^^^^^^^^^^^^^^^^^^^^^^^^^^^^^^^^^^
  File "C:\Users\shahoraiar\Desktop\Travel-Assistant\venv\Lib\site-packages\django\db\models\query.py", line 363, in __repr__
    return "<%s %r>" % (self.__class__.__name__, data)
                                                 ^^^^
  File "C:\Users\shahoraiar\Desktop\Travel-Assistant\venv\Lib\site-packages\django\db\models\base.py", line 590, in __repr__
    return "<%s: %s>" % (self.__class__.__name__, self)
                                                  ^^^^
  File "C:\Users\shahoraiar\Desktop\Travel-Assistant\personalize\models.py", line 31, in __str__
    prefs = ", ".join([p.name for p in self.preferences.all()])
                                       ^^^^^^^^^^^^^^^^^^^^
AttributeError: 'Interest' object has no attribute 'all'
[35;1mHTTP POST /api/personalize/itineraries/create/ 500 [0.03, 172.28.176.1:64949][0m
Internal Server Error: /api/personalize/itineraries/
Traceback (most recent call last):
  File "C:\Users\shahoraiar\Desktop\Travel-Assistant\venv\Lib\site-packages\asgiref\sync.py", line 489, in thread_handler
    raise exc_info[1]
  File "C:\Users\shahoraiar\Desktop\Travel-Assistant\venv\Lib\site-packages\django\core\handlers\exception.py", line 42, in inner
    response = await get_response(request)
               ^^^^^^^^^^^^^^^^^^^^^^^^^^^
  File "C:\Users\shahoraiar\Desktop\Travel-Assistant\venv\Lib\site-packages\asgiref\sync.py", line 489, in thread_handler
    raise exc_info[1]
  File "C:\Users\shahoraiar\Desktop\Travel-Assistant\venv\Lib\site-packages\django\core\handlers\base.py", line 253, in _get_response_async
    response = await wrapped_callback(
               ^^^^^^^^^^^^^^^^^^^^^^^
        request, *callback_args, **callback_kwargs
        ^^^^^^^^^^^^^^^^^^^^^^^^^^^^^^^^^^^^^^^^^^
    )
    ^
  File "C:\Users\shahoraiar\Desktop\Travel-Assistant\venv\Lib\site-packages\asgiref\sync.py", line 439, in __call__
    ret = await asyncio.shield(exec_coro)
          ^^^^^^^^^^^^^^^^^^^^^^^^^^^^^^^
  File "C:\Program Files\Python313\Lib\concurrent\futures\thread.py", line 59, in run
    result = self.fn(*self.args, **self.kwargs)
  File "C:\Users\shahoraiar\Desktop\Travel-Assistant\venv\Lib\site-packages\asgiref\sync.py", line 493, in thread_handler
    return func(*args, **kwargs)
  File "C:\Users\shahoraiar\Desktop\Travel-Assistant\venv\Lib\site-packages\django\views\decorators\csrf.py", line 65, in _view_wrapper
    return view_func(request, *args, **kwargs)
  File "C:\Users\shahoraiar\Desktop\Travel-Assistant\venv\Lib\site-packages\django\views\generic\base.py", line 105, in view
    return self.dispatch(request, *args, **kwargs)
           ~~~~~~~~~~~~~^^^^^^^^^^^^^^^^^^^^^^^^^^
  File "C:\Users\shahoraiar\Desktop\Travel-Assistant\venv\Lib\site-packages\rest_framework\views.py", line 515, in dispatch
    response = self.handle_exception(exc)
  File "C:\Users\shahoraiar\Desktop\Travel-Assistant\venv\Lib\site-packages\rest_framework\views.py", line 475, in handle_exception
    self.raise_uncaught_exception(exc)
    ~~~~~~~~~~~~~~~~~~~~~~~~~~~~~^^^^^
  File "C:\Users\shahoraiar\Desktop\Travel-Assistant\venv\Lib\site-packages\rest_framework\views.py", line 486, in raise_uncaught_exception
    raise exc
  File "C:\Users\shahoraiar\Desktop\Travel-Assistant\venv\Lib\site-packages\rest_framework\views.py", line 512, in dispatch
    response = handler(request, *args, **kwargs)
  File "C:\Users\shahoraiar\Desktop\Travel-Assistant\venv\Lib\site-packages\rest_framework\decorators.py", line 50, in handler
    return func(*args, **kwargs)
  File "C:\Users\shahoraiar\Desktop\Travel-Assistant\personalize\views.py", line 169, in get_itinerary
    return Response(serializer.data)
                    ^^^^^^^^^^^^^^^
  File "C:\Users\shahoraiar\Desktop\Travel-Assistant\venv\Lib\site-packages\rest_framework\serializers.py", line 797, in data
    ret = super().data
          ^^^^^^^^^^^^
  File "C:\Users\shahoraiar\Desktop\Travel-Assistant\venv\Lib\site-packages\rest_framework\serializers.py", line 251, in data
    self._data = self.to_representation(self.instance)
                 ~~~~~~~~~~~~~~~~~~~~~~^^^^^^^^^^^^^^^
  File "C:\Users\shahoraiar\Desktop\Travel-Assistant\venv\Lib\site-packages\rest_framework\serializers.py", line 716, in to_representation
    self.child.to_representation(item) for item in iterable
    ~~~~~~~~~~~~~~~~~~~~~~~~~~~~^^^^^^
  File "C:\Users\shahoraiar\Desktop\Travel-Assistant\venv\Lib\site-packages\rest_framework\serializers.py", line 525, in to_representation
    for field in fields:
                 ^^^^^^
  File "C:\Users\shahoraiar\Desktop\Travel-Assistant\venv\Lib\site-packages\rest_framework\serializers.py", line 386, in _readable_fields
    for field in self.fields.values():
                 ^^^^^^^^^^^
  File "C:\Users\shahoraiar\Desktop\Travel-Assistant\venv\Lib\site-packages\django\utils\functional.py", line 47, in __get__
    res = instance.__dict__[self.name] = self.func(instance)
                                         ~~~~~~~~~^^^^^^^^^^
  File "C:\Users\shahoraiar\Desktop\Travel-Assistant\venv\Lib\site-packages\rest_framework\serializers.py", line 374, in fields
    for key, value in self.get_fields().items():
                      ~~~~~~~~~~~~~~~^^
  File "C:\Users\shahoraiar\Desktop\Travel-Assistant\venv\Lib\site-packages\rest_framework\serializers.py", line 1105, in get_fields
    field_class, field_kwargs = self.build_field(
                                ~~~~~~~~~~~~~~~~^
        source, info, model, depth
        ^^^^^^^^^^^^^^^^^^^^^^^^^^
    )
    ^
  File "C:\Users\shahoraiar\Desktop\Travel-Assistant\venv\Lib\site-packages\rest_framework\serializers.py", line 1251, in build_field
    return self.build_unknown_field(field_name, model_class)
           ~~~~~~~~~~~~~~~~~~~~~~~~^^^^^^^^^^^^^^^^^^^^^^^^^
  File "C:\Users\shahoraiar\Desktop\Travel-Assistant\venv\Lib\site-packages\rest_framework\serializers.py", line 1369, in build_unknown_field
    raise ImproperlyConfigured(
    ...<2 lines>...
    )
django.core.exceptions.ImproperlyConfigured: Field name `destination` is not valid for model `Itinerary` in `personalize.serializers.ItineraryReadSerializer`.
[35;1mHTTP GET /api/personalize/itineraries/ 500 [0.05, 172.28.176.1:64949][0m
Internal Server Error: /api/personalize/itineraries/
Traceback (most recent call last):
  File "C:\Users\shahoraiar\Desktop\Travel-Assistant\venv\Lib\site-packages\asgiref\sync.py", line 489, in thread_handler
    raise exc_info[1]
  File "C:\Users\shahoraiar\Desktop\Travel-Assistant\venv\Lib\site-packages\django\core\handlers\exception.py", line 42, in inner
    response = await get_response(request)
               ^^^^^^^^^^^^^^^^^^^^^^^^^^^
  File "C:\Users\shahoraiar\Desktop\Travel-Assistant\venv\Lib\site-packages\asgiref\sync.py", line 489, in thread_handler
    raise exc_info[1]
  File "C:\Users\shahoraiar\Desktop\Travel-Assistant\venv\Lib\site-packages\django\core\handlers\base.py", line 253, in _get_response_async
    response = await wrapped_callback(
               ^^^^^^^^^^^^^^^^^^^^^^^
        request, *callback_args, **callback_kwargs
        ^^^^^^^^^^^^^^^^^^^^^^^^^^^^^^^^^^^^^^^^^^
    )
    ^
  File "C:\Users\shahoraiar\Desktop\Travel-Assistant\venv\Lib\site-packages\asgiref\sync.py", line 439, in __call__
    ret = await asyncio.shield(exec_coro)
          ^^^^^^^^^^^^^^^^^^^^^^^^^^^^^^^
  File "C:\Program Files\Python313\Lib\concurrent\futures\thread.py", line 59, in run
    result = self.fn(*self.args, **self.kwargs)
  File "C:\Users\shahoraiar\Desktop\Travel-Assistant\venv\Lib\site-packages\asgiref\sync.py", line 493, in thread_handler
    return func(*args, **kwargs)
  File "C:\Users\shahoraiar\Desktop\Travel-Assistant\venv\Lib\site-packages\django\views\decorators\csrf.py", line 65, in _view_wrapper
    return view_func(request, *args, **kwargs)
  File "C:\Users\shahoraiar\Desktop\Travel-Assistant\venv\Lib\site-packages\django\views\generic\base.py", line 105, in view
    return self.dispatch(request, *args, **kwargs)
           ~~~~~~~~~~~~~^^^^^^^^^^^^^^^^^^^^^^^^^^
  File "C:\Users\shahoraiar\Desktop\Travel-Assistant\venv\Lib\site-packages\rest_framework\views.py", line 515, in dispatch
    response = self.handle_exception(exc)
  File "C:\Users\shahoraiar\Desktop\Travel-Assistant\venv\Lib\site-packages\rest_framework\views.py", line 475, in handle_exception
    self.raise_uncaught_exception(exc)
    ~~~~~~~~~~~~~~~~~~~~~~~~~~~~~^^^^^
  File "C:\Users\shahoraiar\Desktop\Travel-Assistant\venv\Lib\site-packages\rest_framework\views.py", line 486, in raise_uncaught_exception
    raise exc
  File "C:\Users\shahoraiar\Desktop\Travel-Assistant\venv\Lib\site-packages\rest_framework\views.py", line 512, in dispatch
    response = handler(request, *args, **kwargs)
  File "C:\Users\shahoraiar\Desktop\Travel-Assistant\venv\Lib\site-packages\rest_framework\decorators.py", line 50, in handler
    return func(*args, **kwargs)
  File "C:\Users\shahoraiar\Desktop\Travel-Assistant\personalize\views.py", line 170, in get_itinerary
    return Response(serializer.data)
                    ^^^^^^^^^^^^^^^
  File "C:\Users\shahoraiar\Desktop\Travel-Assistant\venv\Lib\site-packages\rest_framework\serializers.py", line 797, in data
    ret = super().data
          ^^^^^^^^^^^^
  File "C:\Users\shahoraiar\Desktop\Travel-Assistant\venv\Lib\site-packages\rest_framework\serializers.py", line 251, in data
    self._data = self.to_representation(self.instance)
                 ~~~~~~~~~~~~~~~~~~~~~~^^^^^^^^^^^^^^^
  File "C:\Users\shahoraiar\Desktop\Travel-Assistant\venv\Lib\site-packages\rest_framework\serializers.py", line 716, in to_representation
    self.child.to_representation(item) for item in iterable
    ~~~~~~~~~~~~~~~~~~~~~~~~~~~~^^^^^^
  File "C:\Users\shahoraiar\Desktop\Travel-Assistant\venv\Lib\site-packages\rest_framework\serializers.py", line 525, in to_representation
    for field in fields:
                 ^^^^^^
  File "C:\Users\shahoraiar\Desktop\Travel-Assistant\venv\Lib\site-packages\rest_framework\serializers.py", line 386, in _readable_fields
    for field in self.fields.values():
                 ^^^^^^^^^^^
  File "C:\Users\shahoraiar\Desktop\Travel-Assistant\venv\Lib\site-packages\django\utils\functional.py", line 47, in __get__
    res = instance.__dict__[self.name] = self.func(instance)
                                         ~~~~~~~~~^^^^^^^^^^
  File "C:\Users\shahoraiar\Desktop\Travel-Assistant\venv\Lib\site-packages\rest_framework\serializers.py", line 374, in fields
    for key, value in self.get_fields().items():
                      ~~~~~~~~~~~~~~~^^
  File "C:\Users\shahoraiar\Desktop\Travel-Assistant\venv\Lib\site-packages\rest_framework\serializers.py", line 1105, in get_fields
    field_class, field_kwargs = self.build_field(
                                ~~~~~~~~~~~~~~~~^
        source, info, model, depth
        ^^^^^^^^^^^^^^^^^^^^^^^^^^
    )
    ^
  File "C:\Users\shahoraiar\Desktop\Travel-Assistant\venv\Lib\site-packages\rest_framework\serializers.py", line 1251, in build_field
    return self.build_unknown_field(field_name, model_class)
           ~~~~~~~~~~~~~~~~~~~~~~~~^^^^^^^^^^^^^^^^^^^^^^^^^
  File "C:\Users\shahoraiar\Desktop\Travel-Assistant\venv\Lib\site-packages\rest_framework\serializers.py", line 1369, in build_unknown_field
    raise ImproperlyConfigured(
    ...<2 lines>...
    )
django.core.exceptions.ImproperlyConfigured: Field name `destination` is not valid for model `Itinerary` in `personalize.serializers.ItineraryReadSerializer`.
[35;1mHTTP GET /api/personalize/itineraries/ 500 [0.07, 172.28.176.1:64831][0m
Internal Server Error: /api/personalize/itineraries/
Traceback (most recent call last):
  File "C:\Users\shahoraiar\Desktop\Travel-Assistant\venv\Lib\site-packages\asgiref\sync.py", line 489, in thread_handler
    raise exc_info[1]
  File "C:\Users\shahoraiar\Desktop\Travel-Assistant\venv\Lib\site-packages\django\core\handlers\exception.py", line 42, in inner
    response = await get_response(request)
               ^^^^^^^^^^^^^^^^^^^^^^^^^^^
  File "C:\Users\shahoraiar\Desktop\Travel-Assistant\venv\Lib\site-packages\asgiref\sync.py", line 489, in thread_handler
    raise exc_info[1]
  File "C:\Users\shahoraiar\Desktop\Travel-Assistant\venv\Lib\site-packages\django\core\handlers\base.py", line 253, in _get_response_async
    response = await wrapped_callback(
               ^^^^^^^^^^^^^^^^^^^^^^^
        request, *callback_args, **callback_kwargs
        ^^^^^^^^^^^^^^^^^^^^^^^^^^^^^^^^^^^^^^^^^^
    )
    ^
  File "C:\Users\shahoraiar\Desktop\Travel-Assistant\venv\Lib\site-packages\asgiref\sync.py", line 439, in __call__
    ret = await asyncio.shield(exec_coro)
          ^^^^^^^^^^^^^^^^^^^^^^^^^^^^^^^
  File "C:\Program Files\Python313\Lib\concurrent\futures\thread.py", line 59, in run
    result = self.fn(*self.args, **self.kwargs)
  File "C:\Users\shahoraiar\Desktop\Travel-Assistant\venv\Lib\site-packages\asgiref\sync.py", line 493, in thread_handler
    return func(*args, **kwargs)
  File "C:\Users\shahoraiar\Desktop\Travel-Assistant\venv\Lib\site-packages\django\views\decorators\csrf.py", line 65, in _view_wrapper
    return view_func(request, *args, **kwargs)
  File "C:\Users\shahoraiar\Desktop\Travel-Assistant\venv\Lib\site-packages\django\views\generic\base.py", line 105, in view
    return self.dispatch(request, *args, **kwargs)
           ~~~~~~~~~~~~~^^^^^^^^^^^^^^^^^^^^^^^^^^
  File "C:\Users\shahoraiar\Desktop\Travel-Assistant\venv\Lib\site-packages\rest_framework\views.py", line 515, in dispatch
    response = self.handle_exception(exc)
  File "C:\Users\shahoraiar\Desktop\Travel-Assistant\venv\Lib\site-packages\rest_framework\views.py", line 475, in handle_exception
    self.raise_uncaught_exception(exc)
    ~~~~~~~~~~~~~~~~~~~~~~~~~~~~~^^^^^
  File "C:\Users\shahoraiar\Desktop\Travel-Assistant\venv\Lib\site-packages\rest_framework\views.py", line 486, in raise_uncaught_exception
    raise exc
  File "C:\Users\shahoraiar\Desktop\Travel-Assistant\venv\Lib\site-packages\rest_framework\views.py", line 512, in dispatch
    response = handler(request, *args, **kwargs)
  File "C:\Users\shahoraiar\Desktop\Travel-Assistant\venv\Lib\site-packages\rest_framework\decorators.py", line 50, in handler
    return func(*args, **kwargs)
  File "C:\Users\shahoraiar\Desktop\Travel-Assistant\personalize\views.py", line 170, in get_itinerary
    return Response(serializer.data)
                    ^^^^^^^^^^^^^^^
  File "C:\Users\shahoraiar\Desktop\Travel-Assistant\venv\Lib\site-packages\rest_framework\serializers.py", line 797, in data
    ret = super().data
          ^^^^^^^^^^^^
  File "C:\Users\shahoraiar\Desktop\Travel-Assistant\venv\Lib\site-packages\rest_framework\serializers.py", line 251, in data
    self._data = self.to_representation(self.instance)
                 ~~~~~~~~~~~~~~~~~~~~~~^^^^^^^^^^^^^^^
  File "C:\Users\shahoraiar\Desktop\Travel-Assistant\venv\Lib\site-packages\rest_framework\serializers.py", line 716, in to_representation
    self.child.to_representation(item) for item in iterable
    ~~~~~~~~~~~~~~~~~~~~~~~~~~~~^^^^^^
  File "C:\Users\shahoraiar\Desktop\Travel-Assistant\venv\Lib\site-packages\rest_framework\serializers.py", line 525, in to_representation
    for field in fields:
                 ^^^^^^
  File "C:\Users\shahoraiar\Desktop\Travel-Assistant\venv\Lib\site-packages\rest_framework\serializers.py", line 386, in _readable_fields
    for field in self.fields.values():
                 ^^^^^^^^^^^
  File "C:\Users\shahoraiar\Desktop\Travel-Assistant\venv\Lib\site-packages\django\utils\functional.py", line 47, in __get__
    res = instance.__dict__[self.name] = self.func(instance)
                                         ~~~~~~~~~^^^^^^^^^^
  File "C:\Users\shahoraiar\Desktop\Travel-Assistant\venv\Lib\site-packages\rest_framework\serializers.py", line 374, in fields
    for key, value in self.get_fields().items():
                      ~~~~~~~~~~~~~~~^^
  File "C:\Users\shahoraiar\Desktop\Travel-Assistant\venv\Lib\site-packages\rest_framework\serializers.py", line 1105, in get_fields
    field_class, field_kwargs = self.build_field(
                                ~~~~~~~~~~~~~~~~^
        source, info, model, depth
        ^^^^^^^^^^^^^^^^^^^^^^^^^^
    )
    ^
  File "C:\Users\shahoraiar\Desktop\Travel-Assistant\venv\Lib\site-packages\rest_framework\serializers.py", line 1251, in build_field
    return self.build_unknown_field(field_name, model_class)
           ~~~~~~~~~~~~~~~~~~~~~~~~^^^^^^^^^^^^^^^^^^^^^^^^^
  File "C:\Users\shahoraiar\Desktop\Travel-Assistant\venv\Lib\site-packages\rest_framework\serializers.py", line 1369, in build_unknown_field
    raise ImproperlyConfigured(
    ...<2 lines>...
    )
django.core.exceptions.ImproperlyConfigured: Field name `destination` is not valid for model `Itinerary` in `personalize.serializers.ItineraryReadSerializer`.
[35;1mHTTP GET /api/personalize/itineraries/ 500 [0.05, 172.28.176.1:58794][0m
Internal Server Error: /api/personalize/itineraries/
Traceback (most recent call last):
  File "C:\Users\shahoraiar\Desktop\Travel-Assistant\venv\Lib\site-packages\asgiref\sync.py", line 489, in thread_handler
    raise exc_info[1]
  File "C:\Users\shahoraiar\Desktop\Travel-Assistant\venv\Lib\site-packages\django\core\handlers\exception.py", line 42, in inner
    response = await get_response(request)
               ^^^^^^^^^^^^^^^^^^^^^^^^^^^
  File "C:\Users\shahoraiar\Desktop\Travel-Assistant\venv\Lib\site-packages\asgiref\sync.py", line 489, in thread_handler
    raise exc_info[1]
  File "C:\Users\shahoraiar\Desktop\Travel-Assistant\venv\Lib\site-packages\django\core\handlers\base.py", line 253, in _get_response_async
    response = await wrapped_callback(
               ^^^^^^^^^^^^^^^^^^^^^^^
        request, *callback_args, **callback_kwargs
        ^^^^^^^^^^^^^^^^^^^^^^^^^^^^^^^^^^^^^^^^^^
    )
    ^
  File "C:\Users\shahoraiar\Desktop\Travel-Assistant\venv\Lib\site-packages\asgiref\sync.py", line 439, in __call__
    ret = await asyncio.shield(exec_coro)
          ^^^^^^^^^^^^^^^^^^^^^^^^^^^^^^^
  File "C:\Program Files\Python313\Lib\concurrent\futures\thread.py", line 59, in run
    result = self.fn(*self.args, **self.kwargs)
  File "C:\Users\shahoraiar\Desktop\Travel-Assistant\venv\Lib\site-packages\asgiref\sync.py", line 493, in thread_handler
    return func(*args, **kwargs)
  File "C:\Users\shahoraiar\Desktop\Travel-Assistant\venv\Lib\site-packages\django\views\decorators\csrf.py", line 65, in _view_wrapper
    return view_func(request, *args, **kwargs)
  File "C:\Users\shahoraiar\Desktop\Travel-Assistant\venv\Lib\site-packages\django\views\generic\base.py", line 105, in view
    return self.dispatch(request, *args, **kwargs)
           ~~~~~~~~~~~~~^^^^^^^^^^^^^^^^^^^^^^^^^^
  File "C:\Users\shahoraiar\Desktop\Travel-Assistant\venv\Lib\site-packages\rest_framework\views.py", line 515, in dispatch
    response = self.handle_exception(exc)
  File "C:\Users\shahoraiar\Desktop\Travel-Assistant\venv\Lib\site-packages\rest_framework\views.py", line 475, in handle_exception
    self.raise_uncaught_exception(exc)
    ~~~~~~~~~~~~~~~~~~~~~~~~~~~~~^^^^^
  File "C:\Users\shahoraiar\Desktop\Travel-Assistant\venv\Lib\site-packages\rest_framework\views.py", line 486, in raise_uncaught_exception
    raise exc
  File "C:\Users\shahoraiar\Desktop\Travel-Assistant\venv\Lib\site-packages\rest_framework\views.py", line 512, in dispatch
    response = handler(request, *args, **kwargs)
  File "C:\Users\shahoraiar\Desktop\Travel-Assistant\venv\Lib\site-packages\rest_framework\decorators.py", line 50, in handler
    return func(*args, **kwargs)
  File "C:\Users\shahoraiar\Desktop\Travel-Assistant\personalize\views.py", line 170, in get_itinerary
    return Response(serializer.data)
                    ^^^^^^^^^^^^^^^
  File "C:\Users\shahoraiar\Desktop\Travel-Assistant\venv\Lib\site-packages\rest_framework\serializers.py", line 797, in data
    ret = super().data
          ^^^^^^^^^^^^
  File "C:\Users\shahoraiar\Desktop\Travel-Assistant\venv\Lib\site-packages\rest_framework\serializers.py", line 251, in data
    self._data = self.to_representation(self.instance)
                 ~~~~~~~~~~~~~~~~~~~~~~^^^^^^^^^^^^^^^
  File "C:\Users\shahoraiar\Desktop\Travel-Assistant\venv\Lib\site-packages\rest_framework\serializers.py", line 716, in to_representation
    self.child.to_representation(item) for item in iterable
    ~~~~~~~~~~~~~~~~~~~~~~~~~~~~^^^^^^
  File "C:\Users\shahoraiar\Desktop\Travel-Assistant\venv\Lib\site-packages\rest_framework\serializers.py", line 525, in to_representation
    for field in fields:
                 ^^^^^^
  File "C:\Users\shahoraiar\Desktop\Travel-Assistant\venv\Lib\site-packages\rest_framework\serializers.py", line 386, in _readable_fields
    for field in self.fields.values():
                 ^^^^^^^^^^^
  File "C:\Users\shahoraiar\Desktop\Travel-Assistant\venv\Lib\site-packages\django\utils\functional.py", line 47, in __get__
    res = instance.__dict__[self.name] = self.func(instance)
                                         ~~~~~~~~~^^^^^^^^^^
  File "C:\Users\shahoraiar\Desktop\Travel-Assistant\venv\Lib\site-packages\rest_framework\serializers.py", line 374, in fields
    for key, value in self.get_fields().items():
                      ~~~~~~~~~~~~~~~^^
  File "C:\Users\shahoraiar\Desktop\Travel-Assistant\venv\Lib\site-packages\rest_framework\serializers.py", line 1105, in get_fields
    field_class, field_kwargs = self.build_field(
                                ~~~~~~~~~~~~~~~~^
        source, info, model, depth
        ^^^^^^^^^^^^^^^^^^^^^^^^^^
    )
    ^
  File "C:\Users\shahoraiar\Desktop\Travel-Assistant\venv\Lib\site-packages\rest_framework\serializers.py", line 1251, in build_field
    return self.build_unknown_field(field_name, model_class)
           ~~~~~~~~~~~~~~~~~~~~~~~~^^^^^^^^^^^^^^^^^^^^^^^^^
  File "C:\Users\shahoraiar\Desktop\Travel-Assistant\venv\Lib\site-packages\rest_framework\serializers.py", line 1369, in build_unknown_field
    raise ImproperlyConfigured(
    ...<2 lines>...
    )
django.core.exceptions.ImproperlyConfigured: Field name `destination` is not valid for model `Itinerary` in `personalize.serializers.ItineraryReadSerializer`.
[35;1mHTTP GET /api/personalize/itineraries/ 500 [0.06, 172.28.176.1:52571][0m
Internal Server Error: /api/personalize/itineraries/
Traceback (most recent call last):
  File "C:\Users\shahoraiar\Desktop\Travel-Assistant\venv\Lib\site-packages\asgiref\sync.py", line 489, in thread_handler
    raise exc_info[1]
  File "C:\Users\shahoraiar\Desktop\Travel-Assistant\venv\Lib\site-packages\django\core\handlers\exception.py", line 42, in inner
    response = await get_response(request)
               ^^^^^^^^^^^^^^^^^^^^^^^^^^^
  File "C:\Users\shahoraiar\Desktop\Travel-Assistant\venv\Lib\site-packages\asgiref\sync.py", line 489, in thread_handler
    raise exc_info[1]
  File "C:\Users\shahoraiar\Desktop\Travel-Assistant\venv\Lib\site-packages\django\core\handlers\base.py", line 253, in _get_response_async
    response = await wrapped_callback(
               ^^^^^^^^^^^^^^^^^^^^^^^
        request, *callback_args, **callback_kwargs
        ^^^^^^^^^^^^^^^^^^^^^^^^^^^^^^^^^^^^^^^^^^
    )
    ^
  File "C:\Users\shahoraiar\Desktop\Travel-Assistant\venv\Lib\site-packages\asgiref\sync.py", line 439, in __call__
    ret = await asyncio.shield(exec_coro)
          ^^^^^^^^^^^^^^^^^^^^^^^^^^^^^^^
  File "C:\Program Files\Python313\Lib\concurrent\futures\thread.py", line 59, in run
    result = self.fn(*self.args, **self.kwargs)
  File "C:\Users\shahoraiar\Desktop\Travel-Assistant\venv\Lib\site-packages\asgiref\sync.py", line 493, in thread_handler
    return func(*args, **kwargs)
  File "C:\Users\shahoraiar\Desktop\Travel-Assistant\venv\Lib\site-packages\django\views\decorators\csrf.py", line 65, in _view_wrapper
    return view_func(request, *args, **kwargs)
  File "C:\Users\shahoraiar\Desktop\Travel-Assistant\venv\Lib\site-packages\django\views\generic\base.py", line 105, in view
    return self.dispatch(request, *args, **kwargs)
           ~~~~~~~~~~~~~^^^^^^^^^^^^^^^^^^^^^^^^^^
  File "C:\Users\shahoraiar\Desktop\Travel-Assistant\venv\Lib\site-packages\rest_framework\views.py", line 515, in dispatch
    response = self.handle_exception(exc)
  File "C:\Users\shahoraiar\Desktop\Travel-Assistant\venv\Lib\site-packages\rest_framework\views.py", line 475, in handle_exception
    self.raise_uncaught_exception(exc)
    ~~~~~~~~~~~~~~~~~~~~~~~~~~~~~^^^^^
  File "C:\Users\shahoraiar\Desktop\Travel-Assistant\venv\Lib\site-packages\rest_framework\views.py", line 486, in raise_uncaught_exception
    raise exc
  File "C:\Users\shahoraiar\Desktop\Travel-Assistant\venv\Lib\site-packages\rest_framework\views.py", line 512, in dispatch
    response = handler(request, *args, **kwargs)
  File "C:\Users\shahoraiar\Desktop\Travel-Assistant\venv\Lib\site-packages\rest_framework\decorators.py", line 50, in handler
    return func(*args, **kwargs)
  File "C:\Users\shahoraiar\Desktop\Travel-Assistant\personalize\views.py", line 170, in get_itinerary
    return Response(serializer.data)
                    ^^^^^^^^^^^^^^^
  File "C:\Users\shahoraiar\Desktop\Travel-Assistant\venv\Lib\site-packages\rest_framework\serializers.py", line 797, in data
    ret = super().data
          ^^^^^^^^^^^^
  File "C:\Users\shahoraiar\Desktop\Travel-Assistant\venv\Lib\site-packages\rest_framework\serializers.py", line 251, in data
    self._data = self.to_representation(self.instance)
                 ~~~~~~~~~~~~~~~~~~~~~~^^^^^^^^^^^^^^^
  File "C:\Users\shahoraiar\Desktop\Travel-Assistant\venv\Lib\site-packages\rest_framework\serializers.py", line 716, in to_representation
    self.child.to_representation(item) for item in iterable
    ~~~~~~~~~~~~~~~~~~~~~~~~~~~~^^^^^^
  File "C:\Users\shahoraiar\Desktop\Travel-Assistant\venv\Lib\site-packages\rest_framework\serializers.py", line 525, in to_representation
    for field in fields:
                 ^^^^^^
  File "C:\Users\shahoraiar\Desktop\Travel-Assistant\venv\Lib\site-packages\rest_framework\serializers.py", line 386, in _readable_fields
    for field in self.fields.values():
                 ^^^^^^^^^^^
  File "C:\Users\shahoraiar\Desktop\Travel-Assistant\venv\Lib\site-packages\django\utils\functional.py", line 47, in __get__
    res = instance.__dict__[self.name] = self.func(instance)
                                         ~~~~~~~~~^^^^^^^^^^
  File "C:\Users\shahoraiar\Desktop\Travel-Assistant\venv\Lib\site-packages\rest_framework\serializers.py", line 374, in fields
    for key, value in self.get_fields().items():
                      ~~~~~~~~~~~~~~~^^
  File "C:\Users\shahoraiar\Desktop\Travel-Assistant\venv\Lib\site-packages\rest_framework\serializers.py", line 1105, in get_fields
    field_class, field_kwargs = self.build_field(
                                ~~~~~~~~~~~~~~~~^
        source, info, model, depth
        ^^^^^^^^^^^^^^^^^^^^^^^^^^
    )
    ^
  File "C:\Users\shahoraiar\Desktop\Travel-Assistant\venv\Lib\site-packages\rest_framework\serializers.py", line 1251, in build_field
    return self.build_unknown_field(field_name, model_class)
           ~~~~~~~~~~~~~~~~~~~~~~~~^^^^^^^^^^^^^^^^^^^^^^^^^
  File "C:\Users\shahoraiar\Desktop\Travel-Assistant\venv\Lib\site-packages\rest_framework\serializers.py", line 1369, in build_unknown_field
    raise ImproperlyConfigured(
    ...<2 lines>...
    )
django.core.exceptions.ImproperlyConfigured: Field name `destination` is not valid for model `Itinerary` in `personalize.serializers.ItineraryReadSerializer`.
[35;1mHTTP GET /api/personalize/itineraries/ 500 [0.03, 172.28.176.1:52571][0m
Internal Server Error: /api/personalize/itineraries/create/
Traceback (most recent call last):
  File "C:\Users\shahoraiar\Desktop\Travel-Assistant\venv\Lib\site-packages\asgiref\sync.py", line 489, in thread_handler
    raise exc_info[1]
  File "C:\Users\shahoraiar\Desktop\Travel-Assistant\venv\Lib\site-packages\django\core\handlers\exception.py", line 42, in inner
    response = await get_response(request)
               ^^^^^^^^^^^^^^^^^^^^^^^^^^^
  File "C:\Users\shahoraiar\Desktop\Travel-Assistant\venv\Lib\site-packages\asgiref\sync.py", line 489, in thread_handler
    raise exc_info[1]
  File "C:\Users\shahoraiar\Desktop\Travel-Assistant\venv\Lib\site-packages\django\core\handlers\base.py", line 253, in _get_response_async
    response = await wrapped_callback(
               ^^^^^^^^^^^^^^^^^^^^^^^
        request, *callback_args, **callback_kwargs
        ^^^^^^^^^^^^^^^^^^^^^^^^^^^^^^^^^^^^^^^^^^
    )
    ^
  File "C:\Users\shahoraiar\Desktop\Travel-Assistant\venv\Lib\site-packages\asgiref\sync.py", line 439, in __call__
    ret = await asyncio.shield(exec_coro)
          ^^^^^^^^^^^^^^^^^^^^^^^^^^^^^^^
  File "C:\Program Files\Python313\Lib\concurrent\futures\thread.py", line 59, in run
    result = self.fn(*self.args, **self.kwargs)
  File "C:\Users\shahoraiar\Desktop\Travel-Assistant\venv\Lib\site-packages\asgiref\sync.py", line 493, in thread_handler
    return func(*args, **kwargs)
  File "C:\Users\shahoraiar\Desktop\Travel-Assistant\venv\Lib\site-packages\django\views\decorators\csrf.py", line 65, in _view_wrapper
    return view_func(request, *args, **kwargs)
  File "C:\Users\shahoraiar\Desktop\Travel-Assistant\venv\Lib\site-packages\django\views\generic\base.py", line 105, in view
    return self.dispatch(request, *args, **kwargs)
           ~~~~~~~~~~~~~^^^^^^^^^^^^^^^^^^^^^^^^^^
  File "C:\Users\shahoraiar\Desktop\Travel-Assistant\venv\Lib\site-packages\rest_framework\views.py", line 515, in dispatch
    response = self.handle_exception(exc)
  File "C:\Users\shahoraiar\Desktop\Travel-Assistant\venv\Lib\site-packages\rest_framework\views.py", line 475, in handle_exception
    self.raise_uncaught_exception(exc)
    ~~~~~~~~~~~~~~~~~~~~~~~~~~~~~^^^^^
  File "C:\Users\shahoraiar\Desktop\Travel-Assistant\venv\Lib\site-packages\rest_framework\views.py", line 486, in raise_uncaught_exception
    raise exc
  File "C:\Users\shahoraiar\Desktop\Travel-Assistant\venv\Lib\site-packages\rest_framework\views.py", line 512, in dispatch
    response = handler(request, *args, **kwargs)
  File "C:\Users\shahoraiar\Desktop\Travel-Assistant\venv\Lib\site-packages\rest_framework\decorators.py", line 50, in handler
    return func(*args, **kwargs)
  File "C:\Users\shahoraiar\Desktop\Travel-Assistant\personalize\views.py", line 139, in create_itinerary
    print('user preferences: ', user_preferences)
    ~~~~~^^^^^^^^^^^^^^^^^^^^^^^^^^^^^^^^^^^^^^^^
  File "C:\Users\shahoraiar\Desktop\Travel-Assistant\venv\Lib\site-packages\django\db\models\query.py", line 363, in __repr__
    return "<%s %r>" % (self.__class__.__name__, data)
                                                 ^^^^
  File "C:\Users\shahoraiar\Desktop\Travel-Assistant\venv\Lib\site-packages\django\db\models\base.py", line 590, in __repr__
    return "<%s: %s>" % (self.__class__.__name__, self)
                                                  ^^^^
  File "C:\Users\shahoraiar\Desktop\Travel-Assistant\personalize\models.py", line 31, in __str__
    prefs = ", ".join([p.name for p in self.preferences.all()])
                                       ^^^^^^^^^^^^^^^^^^^^
AttributeError: 'Interest' object has no attribute 'all'
[35;1mHTTP POST /api/personalize/itineraries/create/ 500 [0.03, 172.28.176.1:52571][0m
